Traceback (most recent call last):
  File "/home/ubuntu/.local/bin/uvicorn", line 8, in <module>
    sys.exit(main())
             ~~~~^^
  File "/home/ubuntu/.local/lib/python3.13/site-packages/click/core.py", line 1442, in __call__
    return self.main(*args, **kwargs)
           ~~~~~~~~~^^^^^^^^^^^^^^^^^
  File "/home/ubuntu/.local/lib/python3.13/site-packages/click/core.py", line 1363, in main
    rv = self.invoke(ctx)
  File "/home/ubuntu/.local/lib/python3.13/site-packages/click/core.py", line 1226, in invoke
    return ctx.invoke(self.callback, **ctx.params)
           ~~~~~~~~~~^^^^^^^^^^^^^^^^^^^^^^^^^^^^^
  File "/home/ubuntu/.local/lib/python3.13/site-packages/click/core.py", line 794, in invoke
    return callback(*args, **kwargs)
  File "/home/ubuntu/.local/lib/python3.13/site-packages/uvicorn/main.py", line 410, in main
    run(
    ~~~^
        app,
        ^^^^
    ...<44 lines>...
        h11_max_incomplete_event_size=h11_max_incomplete_event_size,
        ^^^^^^^^^^^^^^^^^^^^^^^^^^^^^^^^^^^^^^^^^^^^^^^^^^^^^^^^^^^^
    )
    ^
  File "/home/ubuntu/.local/lib/python3.13/site-packages/uvicorn/main.py", line 578, in run
    server.run()
    ~~~~~~~~~~^^
  File "/home/ubuntu/.local/lib/python3.13/site-packages/uvicorn/server.py", line 61, in run
    return asyncio.run(self.serve(sockets=sockets))
           ~~~~~~~~~~~^^^^^^^^^^^^^^^^^^^^^^^^^^^^^
  File "/usr/lib/python3.13/asyncio/runners.py", line 195, in run
    return runner.run(main)
           ~~~~~~~~~~^^^^^^
  File "/usr/lib/python3.13/asyncio/runners.py", line 118, in run
    return self._loop.run_until_complete(task)
           ~~~~~~~~~~~~~~~~~~~~~~~~~~~~~^^^^^^
  File "uvloop/loop.pyx", line 1518, in uvloop.loop.Loop.run_until_complete
  File "/home/ubuntu/.local/lib/python3.13/site-packages/uvicorn/server.py", line 68, in serve
    config.load()
    ~~~~~~~~~~~^^
  File "/home/ubuntu/.local/lib/python3.13/site-packages/uvicorn/config.py", line 473, in load
    self.loaded_app = import_from_string(self.app)
                      ~~~~~~~~~~~~~~~~~~^^^^^^^^^^
  File "/home/ubuntu/.local/lib/python3.13/site-packages/uvicorn/importer.py", line 21, in import_from_string
    module = importlib.import_module(module_str)
  File "/usr/lib/python3.13/importlib/__init__.py", line 88, in import_module
    return _bootstrap._gcd_import(name[level:], package, level)
           ~~~~~~~~~~~~~~~~~~~~~~^^^^^^^^^^^^^^^^^^^^^^^^^^^^^^
  File "<frozen importlib._bootstrap>", line 1387, in _gcd_import
  File "<frozen importlib._bootstrap>", line 1360, in _find_and_load
  File "<frozen importlib._bootstrap>", line 1331, in _find_and_load_unlocked
  File "<frozen importlib._bootstrap>", line 935, in _load_unlocked
  File "<frozen importlib._bootstrap_external>", line 1026, in exec_module
  File "<frozen importlib._bootstrap>", line 488, in _call_with_frames_removed
  File "/workspace/ai_search_demo/app/main.py", line 1, in <module>
    from fastapi import FastAPI, Query
  File "/home/ubuntu/.local/lib/python3.13/site-packages/fastapi/__init__.py", line 7, in <module>
    from .applications import FastAPI as FastAPI
  File "/home/ubuntu/.local/lib/python3.13/site-packages/fastapi/applications.py", line 16, in <module>
    from fastapi import routing
  File "/home/ubuntu/.local/lib/python3.13/site-packages/fastapi/routing.py", line 24, in <module>
    from fastapi.dependencies.models import Dependant
  File "/home/ubuntu/.local/lib/python3.13/site-packages/fastapi/dependencies/models.py", line 3, in <module>
    from fastapi.security.base import SecurityBase
  File "/home/ubuntu/.local/lib/python3.13/site-packages/fastapi/security/__init__.py", line 1, in <module>
    from .api_key import APIKeyCookie as APIKeyCookie
  File "/home/ubuntu/.local/lib/python3.13/site-packages/fastapi/security/api_key.py", line 3, in <module>
    from fastapi.openapi.models import APIKey, APIKeyIn
  File "/home/ubuntu/.local/lib/python3.13/site-packages/fastapi/openapi/models.py", line 103, in <module>
    class Schema(BaseModel):
    ...<38 lines>...
            extra: str = "allow"
  File "/home/ubuntu/.local/lib/python3.13/site-packages/pydantic/main.py", line 286, in __new__
    cls.__try_update_forward_refs__()
    ~~~~~~~~~~~~~~~~~~~~~~~~~~~~~~~^^
  File "/home/ubuntu/.local/lib/python3.13/site-packages/pydantic/main.py", line 807, in __try_update_forward_refs__
    update_model_forward_refs(cls, cls.__fields__.values(), cls.__config__.json_encoders, localns, (NameError,))
    ~~~~~~~~~~~~~~~~~~~~~~~~~^^^^^^^^^^^^^^^^^^^^^^^^^^^^^^^^^^^^^^^^^^^^^^^^^^^^^^^^^^^^^^^^^^^^^^^^^^^^^^^^^^^
  File "/home/ubuntu/.local/lib/python3.13/site-packages/pydantic/typing.py", line 554, in update_model_forward_refs
    update_field_forward_refs(f, globalns=globalns, localns=localns)
    ~~~~~~~~~~~~~~~~~~~~~~~~~^^^^^^^^^^^^^^^^^^^^^^^^^^^^^^^^^^^^^^^
  File "/home/ubuntu/.local/lib/python3.13/site-packages/pydantic/typing.py", line 520, in update_field_forward_refs
    field.type_ = evaluate_forwardref(field.type_, globalns, localns or None)
                  ~~~~~~~~~~~~~~~~~~~^^^^^^^^^^^^^^^^^^^^^^^^^^^^^^^^^^^^^^^^
  File "/home/ubuntu/.local/lib/python3.13/site-packages/pydantic/typing.py", line 66, in evaluate_forwardref
    return cast(Any, type_)._evaluate(globalns, localns, set())
           ~~~~~~~~~~~~~~~~~~~~~~~~~~^^^^^^^^^^^^^^^^^^^^^^^^^^
TypeError: ForwardRef._evaluate() missing 1 required keyword-only argument: 'recursive_guard'
